Workbook

Sheet Summary
B2: Results analysis summary: Monthly overview | E2: Report generated: 10/08/2026 12:28
B6: Hello,
B7: ="Below is a summary of the 3 months of readings for Jensen Beach AHU 1 ("&TEXT('Monthly metrics'!$D$11,"#,##0")&" readings, 12/01/2025 – 02/25/2026), and our recommendations." -> Below is a summary of the 3 months of readings for Jensen Beach AHU 1 (8,111 readings, 12/01/2025 – 02/25/2026), and our recommendations.
B8: Use the tabs at the bottom to find more detail about each month, including event-level actions.
B9: Read the Guide | C9: See the charts (go to 'Dashboard')
B11: December 2025 / Sensor: Jensen Beach AHU 1 (°F) | D11: ="Rank by mean materiality: "&'Monthly metrics'!$AB$8&" out of 3 months · extremes "&TEXT('Monthly metrics'!$J$8,"0%")&" of readings" -> Rank by mean materiality: 3 out of 3 months · extremes 12% of readings | E11: Status: | F11: 4 recommendations
B13: Improve | C13: Recommendations | D13: Why have we recommended this? | F13: Learn more
B14: Operating level | C14: ● Review what changed when the level shifted | D14: ="Confirmed shift share: "&TEXT('Monthly metrics'!$P$8,"0%")&" of readings ("&TEXT('Monthly metrics'!$N$8*'Monthly metrics'!$D$5/60,"0")&" h). The value stayed away from its baseline for 7+ readings with mean |Z| ≥ 1.2 - check setpoint or schedule changes, sensor drift or an equipment fault." -> Confirmed shift share: 19% of readings (143 h). The value stayed away from its baseline for 7+ readings with mean |Z| ≥ 1.2 - check setpoint or schedule changes, sensor drift or an equipment fault. | F14: Confirmed/Materialized Shift
B15: Daily cycle | C15: ● Check the day/night pattern before acting on single extremes | D15: ="Upper extremes happen mostly by day and lower extremes mostly at night ("&TEXT('Monthly metrics'!$K$8,"0")&" upper, "&TEXT('Monthly metrics'!$L$8,"0")&" lower). With a 20-reading (5 h) baseline, the normal daily swing itself is flagged. If the swing is intended (setback), consider Window = 96 (24 h)." -> Upper extremes happen mostly by day and lower extremes mostly at night (137 upper, 235 lower). With a 20-reading (5 h) baseline, the normal daily swing itself is flagged. If the swing is intended (setback), consider Window = 96 (24 h). | F15: Window (W)
B16: Stability | C16: ● Check for hunting or short-cycling | D16: ="Material changes: "&TEXT('Monthly metrics'!$S$8,"0.0")&" per day - fast changes that repeat within 10 readings. Check valve/damper control loops and compressor or fan staging." -> Material changes: 4.3 per day - fast changes that repeat within 10 readings. Check valve/damper control loops and compressor or fan staging. | F16: MaterialChangeFlag
B17: Data quality | C17: ● Fix the data gaps | D17: ="Missing data: "&TEXT('Monthly metrics'!$X$8,"0.0")&" h in gaps longer than three intervals. Events inside a gap cannot be detected." -> Missing data: 54.8 h in gaps longer than three intervals. Events inside a gap cannot be detected. | F17: Data gaps
C19: Show events and benchmarks for this month (go to 'Dec 2025')
B22: January 2026 / Sensor: Jensen Beach AHU 1 (°F) | D22: ="Rank by mean materiality: "&'Monthly metrics'!$AB$9&" out of 3 months · extremes "&TEXT('Monthly metrics'!$J$9,"0%")&" of readings" -> Rank by mean materiality: 2 out of 3 months · extremes 12% of readings | E22: Status: | F22: 4 recommendations
B24: Improve | C24: Recommendations | D24: Why have we recommended this? | F24: Learn more
B25: Operating level | C25: ● Review what changed when the level shifted | D25: ="Confirmed shift share: "&TEXT('Monthly metrics'!$P$9,"0%")&" of readings ("&TEXT('Monthly metrics'!$N$9*'Monthly metrics'!$D$5/60,"0")&" h). The value stayed away from its baseline for 7+ readings with mean |Z| ≥ 1.2 - check setpoint or schedule changes, sensor drift or an equipment fault." -> Confirmed shift share: 25% of readings (175 h). The value stayed away from its baseline for 7+ readings with mean |Z| ≥ 1.2 - check setpoint or schedule changes, sensor drift or an equipment fault. | F25: Confirmed/Materialized Shift
B26: Daily cycle | C26: ● Check the day/night pattern before acting on single extremes | D26: ="Upper extremes happen mostly by day and lower extremes mostly at night ("&TEXT('Monthly metrics'!$K$9,"0")&" upper, "&TEXT('Monthly metrics'!$L$9,"0")&" lower). With a 20-reading (5 h) baseline, the normal daily swing itself is flagged. If the swing is intended (setback), consider Window = 96 (24 h)." -> Upper extremes happen mostly by day and lower extremes mostly at night (171 upper, 171 lower). With a 20-reading (5 h) baseline, the normal daily swing itself is flagged. If the swing is intended (setback), consider Window = 96 (24 h). | F26: Window (W)
B27: Stability | C27: ● Check for hunting or short-cycling | D27: ="Material changes: "&TEXT('Monthly metrics'!$S$9,"0.0")&" per day - fast changes that repeat within 10 readings. Check valve/damper control loops and compressor or fan staging." -> Material changes: 4.1 per day - fast changes that repeat within 10 readings. Check valve/damper control loops and compressor or fan staging. | F27: MaterialChangeFlag
B28: Data quality | C28: ● Fix the data gaps | D28: ="Missing data: "&TEXT('Monthly metrics'!$X$9,"0.0")&" h in gaps longer than three intervals. Events inside a gap cannot be detected." -> Missing data: 60.7 h in gaps longer than three intervals. Events inside a gap cannot be detected. | F28: Data gaps
C30: Show events and benchmarks for this month (go to 'Jan 2026')
B33: February 2026 / Sensor: Jensen Beach AHU 1 (°F) | D33: ="Rank by mean materiality: "&'Monthly metrics'!$AB$10&" out of 3 months · extremes "&TEXT('Monthly metrics'!$J$10,"0%")&" of readings" -> Rank by mean materiality: 1 out of 3 months · extremes 13% of readings | E33: Status: | F33: 4 recommendations
B35: Improve | C35: Recommendations | D35: Why have we recommended this? | F35: Learn more
B36: Operating level | C36: ● Review what changed when the level shifted | D36: ="Confirmed shift share: "&TEXT('Monthly metrics'!$P$10,"0%")&" of readings ("&TEXT('Monthly metrics'!$N$10*'Monthly metrics'!$D$5/60,"0")&" h). The value stayed away from its baseline for 7+ readings with mean |Z| ≥ 1.2 - check setpoint or schedule changes, sensor drift or an equipment fault." -> Confirmed shift share: 33% of readings (190 h). The value stayed away from its baseline for 7+ readings with mean |Z| ≥ 1.2 - check setpoint or schedule changes, sensor drift or an equipment fault. | F36: Confirmed/Materialized Shift
B37: Daily cycle | C37: ● Check the day/night pattern before acting on single extremes | D37: ="Upper extremes happen mostly by day and lower extremes mostly at night ("&TEXT('Monthly metrics'!$K$10,"0")&" upper, "&TEXT('Monthly metrics'!$L$10,"0")&" lower). With a 20-reading (5 h) baseline, the normal daily swing itself is flagged. If the swing is intended (setback), consider Window = 96 (24 h)." -> Upper extremes happen mostly by day and lower extremes mostly at night (170 upper, 123 lower). With a 20-reading (5 h) baseline, the normal daily swing itself is flagged. If the swing is intended (setback), consider Window = 96 (24 h). | F37: Window (W)
B38: Stability | C38: ● Check for hunting or short-cycling | D38: ="Material changes: "&TEXT('Monthly metrics'!$S$10,"0.0")&" per day - fast changes that repeat within 10 readings. Check valve/damper control loops and compressor or fan staging." -> Material changes: 3.2 per day - fast changes that repeat within 10 readings. Check valve/damper control loops and compressor or fan staging. | F38: MaterialChangeFlag
B39: Data quality | C39: ● Fix the data gaps | D39: ="Missing data: "&TEXT('Monthly metrics'!$X$10,"0.0")&" h in gaps longer than three intervals. Events inside a gap cannot be detected." -> Missing data: 40.4 h in gaps longer than three intervals. Events inside a gap cannot be detected. | F39: Data gaps
C41: Show events and benchmarks for this month (go to 'Feb 2026')
B44: Data quality / Gaps in the readings | D44: =TEXT('Data gaps'!D11,"0")&" gaps, "&TEXT('Data gaps'!D12,"0.0")&" hours of missing data" -> 12 gaps, 155.9 hours of missing data | E44: Status: | F44: =IF('Data gaps'!D12>=6,"Gaps to review","OK") -> Gaps to review
B46: Show the gaps (go to 'Data gaps')

Sheet Dashboard
B2: Dashboard | S2: Report generated: 10/08/2026 12:28
B5: < Back to summary worksheet
B6: Charts for the whole period, drawn from the Data tab. The monthly figures behind them are in the table below (live formulas).
B8: Monthly figures
B9: Month | C9: Extreme share | D9: Confirmed share | E9: Sustained (h) | F9: Material changes/day | G9: Investigate | H9: Review | I9: Monitor | J9: Upper – Day | K9: Upper – Night | L9: Lower – Day | M9: Lower – Night
B10: ='Monthly metrics'!$B$8 -> Dec 2025 | C10: ='Monthly metrics'!$J$8 -> 0.12269129 | D10: ='Monthly metrics'!$P$8 -> 0.18799472 | E10: ='Monthly metrics'!$O$8 -> 235.78333 | F10: ='Monthly metrics'!$S$8 -> 4.2903226 | G10: =COUNTIFS(Events!$L:$L,'Monthly metrics'!$C$8,Events!$M:$M,"Investigate") -> 81 | H10: =COUNTIFS(Events!$L:$L,'Monthly metrics'!$C$8,Events!$M:$M,"Review") -> 19 | I10: =COUNTIFS(Events!$L:$L,'Monthly metrics'!$C$8,Events!$M:$M,"Monitor") -> 22 | J10: =COUNTIFS(D_Month,'Monthly metrics'!$C$8,D_Dir,"upper",D_DN,"Day") -> 94 | K10: =COUNTIFS(D_Month,'Monthly metrics'!$C$8,D_Dir,"upper",D_DN,"Night") -> 43 | L10: =COUNTIFS(D_Month,'Monthly metrics'!$C$8,D_Dir,"lower",D_DN,"Day") -> 113 | M10: =COUNTIFS(D_Month,'Monthly metrics'!$C$8,D_Dir,"lower",D_DN,"Night") -> 122
B11: ='Monthly metrics'!$B$9 -> Jan 2026 | C11: ='Monthly metrics'!$J$9 -> 0.12149201 | D11: ='Monthly metrics'!$P$9 -> 0.24795737 | E11: ='Monthly metrics'!$O$9 -> 251.335 | F11: ='Monthly metrics'!$S$9 -> 4.1 | G11: =COUNTIFS(Events!$L:$L,'Monthly metrics'!$C$9,Events!$M:$M,"Investigate") -> 59 | H11: =COUNTIFS(Events!$L:$L,'Monthly metrics'!$C$9,Events!$M:$M,"Review") -> 29 | I11: =COUNTIFS(Events!$L:$L,'Monthly metrics'!$C$9,Events!$M:$M,"Monitor") -> 14 | J11: =COUNTIFS(D_Month,'Monthly metrics'!$C$9,D_Dir,"upper",D_DN,"Day") -> 141 | K11: =COUNTIFS(D_Month,'Monthly metrics'!$C$9,D_Dir,"upper",D_DN,"Night") -> 30 | L11: =COUNTIFS(D_Month,'Monthly metrics'!$C$9,D_Dir,"lower",D_DN,"Day") -> 61 | M11: =COUNTIFS(D_Month,'Monthly metrics'!$C$9,D_Dir,"lower",D_DN,"Night") -> 110
B12: ='Monthly metrics'!$B$10 -> Feb 2026 | C12: ='Monthly metrics'!$J$10 -> 0.12941696 | D12: ='Monthly metrics'!$P$10 -> 0.33392226 | E12: ='Monthly metrics'!$O$10 -> 246.31833 | F12: ='Monthly metrics'!$S$10 -> 3.24 | G12: =COUNTIFS(Events!$L:$L,'Monthly metrics'!$C$10,Events!$M:$M,"Investigate") -> 49 | H12: =COUNTIFS(Events!$L:$L,'Monthly metrics'!$C$10,Events!$M:$M,"Review") -> 11 | I12: =COUNTIFS(Events!$L:$L,'Monthly metrics'!$C$10,Events!$M:$M,"Monitor") -> 5 | J12: =COUNTIFS(D_Month,'Monthly metrics'!$C$10,D_Dir,"upper",D_DN,"Day") -> 164 | K12: =COUNTIFS(D_Month,'Monthly metrics'!$C$10,D_Dir,"upper",D_DN,"Night") -> 6 | L12: =COUNTIFS(D_Month,'Monthly metrics'!$C$10,D_Dir,"lower",D_DN,"Day") -> 29 | M12: =COUNTIFS(D_Month,'Monthly metrics'!$C$10,D_Dir,"lower",D_DN,"Night") -> 94
B15: By month
B47: Events and extremes
B68: Time of day
B89: By day

Sheet Guide
B2: Guide
B6: This report summarises the Extreme & Change analysis of Jensen Beach AHU 1 and gives recommendations and benchmarks for each month.
B7: It shows when the readings left their normal range, how long deviations lasted, how often the value changed abnormally fast, and how much data is missing.
B9: How to use this report
B10: Use the tabs at the bottom of the screen to move through the workbook.
B12: Tab (at the bottom of the screen) | D12: What is on the tab?
B13: Summary | D13: Overview of each month with recommendations, and links to the month tabs.
B15: Month tabs | D15: ● Analysis funnel: extreme share, sustained deviation hours and material changes per day, with the month's rank.
D16: ● Recommendations with this month vs the best and worst month.
D17: ● More benchmarks, including the same figures for day and night.
D18: ● Every event in the month, sorted by materiality; click the Action to jump to the readings.
B20: Data gaps | D20: Every break in the data longer than three reading intervals, with the hours missing.
B22: Events | D22: All events in the whole period in one filterable list.
B24: Daily overview | D24: One row per day: readings, value range, extremes, persistent and confirmed periods, changes, peak materiality.
B26: Monthly metrics | D26: The calculation table behind the Summary and month tabs (all formulas). The reading interval can be changed here.
B28: Column descriptor | D28: What every column of the results file means, which parameters drive it, and the settings used for this run.
B30: Data | D30: The results file Jensen_Beach_Results_Analysis.csv as exported by the app, plus three helper columns. Rows are in time order (UTC), so the local time repeats once when daylight saving ends.
B32: How are the results calculated?
B33: Each reading is compared with a rolling baseline of the previous 20 readings (about 5 hours). |Z| ≥ 2 flags an Extreme reading.
B34: An event continues while |Z| ≥ 1; after 3 readings it is Persistent, after 7 readings with mean |Z| ≥ 1.2 it is a Confirmed/Materialized Shift.
B35: The rate of change has its own baseline; |Z_ROC| ≥ 2 is an Abnormal Change, and 2 or more within 10 readings make a Material Change.
B36: The Materiality score (0–1) combines size (|Z|), duration and recurrence. Rank 1 = the month with the most issues.
B37: Recommendations are rules applied to these figures; they point to what to check, they are not a diagnosis of the equipment.
B39: Learn more: info_main\Statistical_calc_parameters\Statistical calc parameters manual.docx

Sheet Data gaps
B2: Data gaps | J2: Report generated: 10/08/2026 12:28
B6: The analysis expects one reading about every 15 minutes.
B7: A gap is any break of more than three reading intervals. No readings, and so no extremes or events, exist inside a gap.
B8: This tab lists every gap and the time it covers, so missing data is not mistaken for normal operation.
B10: Summary of gaps
B11: Number of gaps | D11: =COUNT(D15:D26) -> 12
B12: Missing time (hours) | D12: =SUM(D15:D26) -> 155.89056
B14: From (last reading) | C14: To (next reading) | D14: Hours missing | E14: Readings missing (approx.) | F14: Day/Night at start | G14: Severity | H14: Action | I14: Month key
B15: 46022.266 | C15: 46024.551 | D15: 54.822778 | E15: =ROUND(D15*60/'Monthly metrics'!$D$5,0)-1 -> 218 | F15: Night | G15: High | H15: Check the logger / network for this period | I15: 202512
B16: 46038.144 | C16: 46038.408 | D16: 6.3411111 | E16: =ROUND(D16*60/'Monthly metrics'!$D$5,0)-1 -> 24 | F16: Night | G16: Medium | H16: Check the logger / network for this period | I16: 202601
B17: 46041.267 | C17: 46042.479 | D17: 29.106389 | E17: =ROUND(D17*60/'Monthly metrics'!$D$5,0)-1 -> 115 | F17: Night | G17: High | H17: Check the logger / network for this period | I17: 202601
B18: 46050.185 | C18: 46050.41 | D18: 5.4036111 | E18: =ROUND(D18*60/'Monthly metrics'!$D$5,0)-1 -> 21 | F18: Night | G18: Low | H18: Monitor | I18: 202601
B19: 46051.113 | C19: 46051.405 | D19: 7.0116667 | E19: =ROUND(D19*60/'Monthly metrics'!$D$5,0)-1 -> 27 | F19: Night | G19: Medium | H19: Check the logger / network for this period | I19: 202601
B20: 46053.935 | C20: 46054.47 | D20: 12.851111 | E20: =ROUND(D20*60/'Monthly metrics'!$D$5,0)-1 -> 50 | F20: Night | G20: Medium | H20: Check the logger / network for this period | I20: 202601
B21: 46054.752 | C21: 46055.48 | D21: 17.475556 | E21: =ROUND(D21*60/'Monthly metrics'!$D$5,0)-1 -> 69 | F21: Day | G21: Medium | H21: Check the logger / network for this period | I21: 202602
B22: 46055.771 | C22: 46056.489 | D22: 17.225556 | E22: =ROUND(D22*60/'Monthly metrics'!$D$5,0)-1 -> 68 | F22: Night | G22: Medium | H22: Check the logger / network for this period | I22: 202602
B23: 46056.592 | C23: 46056.649 | D23: 1.3633333 | E23: =ROUND(D23*60/'Monthly metrics'!$D$5,0)-1 -> 4 | F23: Day | G23: Low | H23: Monitor | I23: 202602
B24: 46056.715 | C24: 46056.782 | D24: 1.6144444 | E24: =ROUND(D24*60/'Monthly metrics'!$D$5,0)-1 -> 5 | F24: Day | G24: Low | H24: Monitor | I24: 202602
B25: 46059.854 | C25: 46059.907 | D25: 1.2741667 | E25: =ROUND(D25*60/'Monthly metrics'!$D$5,0)-1 -> 4 | F25: Night | G25: Low | H25: Monitor | I25: 202602
B26: 46060.61 | C26: 46060.669 | D26: 1.4008333 | E26: =ROUND(D26*60/'Monthly metrics'!$D$5,0)-1 -> 5 | F26: Day | G26: Low | H26: Monitor | I26: 202602

Sheet Dec 2025
B2: We compared each reading with its own rolling baseline using the settings below | K2: ="Rank by mean materiality: "&'Monthly metrics'!$AB$8&" of 3 months (1 = most issues)" -> Rank by mean materiality: 3 of 3 months (1 = most issues)
B3: ="Sensor: Jensen Beach AHU 1 (°F), Period: December 2025, Value range: "&TEXT('Monthly metrics'!$G$8,"0.0")&" – "&TEXT('Monthly metrics'!$H$8,"0.0")&" °F" -> Sensor: Jensen Beach AHU 1 (°F), Period: December 2025, Value range: 67.9 – 75.5 °F | K3: Report generated: 10/08/2026 12:28
B5: < Back to summary worksheet
B6: Analysis funnel
B7: ="Readings in this month: "&TEXT('Monthly metrics'!$D$8,"#,##0") -> Readings in this month: 3,032 | F7: vs other months (3) | H7: Recommendations to improve | L7: Why have we recommended this?
D9: Extreme readings | I9: This month | J9: Best month | K9: Worst month
D10: Share of readings | F10: Rank vs other months | H10: ● Review what changed when the level shifted | I10: ='Monthly metrics'!$P$8 -> 0.18799472 | J10: =MIN('Monthly metrics'!$P$8:$P$10) -> 0.18799472 | K10: =MAX('Monthly metrics'!$P$8:$P$10) -> 0.33392226 | L10: ="Confirmed shift share: "&TEXT('Monthly metrics'!$P$8,"0%")&" of readings ("&TEXT('Monthly metrics'!$N$8*'Monthly metrics'!$D$5/60,"0")&" h). The value stayed away from its baseline for 7+ readings with mean |Z| ≥ 1.2 - check setpoint or schedule changes, sensor drift or an equipment fault." -> Confirmed shift share: 19% of readings (143 h). The value stayed away from its baseline for 7+ readings with mean |Z| ≥ 1.2 - check setpoint or schedule changes, sensor drift or an equipment fault.
D11: ='Monthly metrics'!$J$8 -> 0.12269129 | F11: ='Monthly metrics'!$Y$8 -> 2
D13: Sustained deviations | H13: ● Check the day/night pattern before acting on single extremes | I13: ='Monthly metrics'!$J$8 -> 0.12269129 | J13: =MIN('Monthly metrics'!$J$8:$J$10) -> 0.12149201 | K13: =MAX('Monthly metrics'!$J$8:$J$10) -> 0.12941696 | L13: ="Upper extremes happen mostly by day and lower extremes mostly at night ("&TEXT('Monthly metrics'!$K$8,"0")&" upper, "&TEXT('Monthly metrics'!$L$8,"0")&" lower). With a 20-reading (5 h) baseline, the normal daily swing itself is flagged. If the swing is intended (setback), consider Window = 96 (24 h)." -> Upper extremes happen mostly by day and lower extremes mostly at night (137 upper, 235 lower). With a 20-reading (5 h) baseline, the normal daily swing itself is flagged. If the swing is intended (setback), consider Window = 96 (24 h).
D14: Hours (Persistent + Confirmed) | F14: Rank vs other months
D15: ='Monthly metrics'!$O$8 -> 235.78333 | F15: ='Monthly metrics'!$Z$8 -> 3
H16: ● Check for hunting or short-cycling | I16: ='Monthly metrics'!$S$8 -> 4.2903226 | J16: =MIN('Monthly metrics'!$S$8:$S$10) -> 3.24 | K16: =MAX('Monthly metrics'!$S$8:$S$10) -> 4.2903226 | L16: ="Material changes: "&TEXT('Monthly metrics'!$S$8,"0.0")&" per day - fast changes that repeat within 10 readings. Check valve/damper control loops and compressor or fan staging." -> Material changes: 4.3 per day - fast changes that repeat within 10 readings. Check valve/damper control loops and compressor or fan staging.
D17: Material changes
D18: Per day | F18: Rank vs other months
D19: ='Monthly metrics'!$S$8 -> 4.2903226 | F19: ='Monthly metrics'!$AA$8 -> 1 | H19: ● Fix the data gaps | I19: ='Monthly metrics'!$X$8 -> 54.822778 | J19: =MIN('Monthly metrics'!$X$8:$X$10) -> 40.353889 | K19: =MAX('Monthly metrics'!$X$8:$X$10) -> 60.713889 | L19: ="Missing data: "&TEXT('Monthly metrics'!$X$8,"0.0")&" h in gaps longer than three intervals. Events inside a gap cannot be detected." -> Missing data: 54.8 h in gaps longer than three intervals. Events inside a gap cannot be detected.
B23: More benchmarks
H24: Measure | I24: This month | J24: Best month | K24: Worst month | L24: Whole period | M24: This month – Day | N24: This month – Night
H25: Mean value | I25: ='Monthly metrics'!$F$8 -> 73.178845 | J25: =MIN('Monthly metrics'!$F$8:$F$10) -> 71.634218 | K25: =MAX('Monthly metrics'!$F$8:$F$10) -> 73.178845 | L25: ='Monthly metrics'!$F$11 -> 72.534323 | M25: =AVERAGEIFS(D_Value,D_Month,'Monthly metrics'!$C$8,D_DN,"Day") -> 73.024759 | N25: =AVERAGEIFS(D_Value,D_Month,'Monthly metrics'!$C$8,D_DN,"Night") -> 73.304011
H26: Min value | I26: ='Monthly metrics'!$G$8 -> 67.8596 | J26: =MIN('Monthly metrics'!$G$8:$G$10) -> 65.0354 | K26: =MAX('Monthly metrics'!$G$8:$G$10) -> 67.8596 | L26: ='Monthly metrics'!$G$11 -> 65.0354 | M26: =_xlfn.MINIFS(D_Value,D_Month,'Monthly metrics'!$C$8,D_DN,"Day") -> 69.836 | N26: =_xlfn.MINIFS(D_Value,D_Month,'Monthly metrics'!$C$8,D_DN,"Night") -> 67.8596
H27: Max value | I27: ='Monthly metrics'!$H$8 -> 75.4826 | J27: =MIN('Monthly metrics'!$H$8:$H$10) -> 74.9174 | K27: =MAX('Monthly metrics'!$H$8:$H$10) -> 75.4826 | L27: ='Monthly metrics'!$H$11 -> 75.4826 | M27: =_xlfn.MAXIFS(D_Value,D_Month,'Monthly metrics'!$C$8,D_DN,"Day") -> 75.4826 | N27: =_xlfn.MAXIFS(D_Value,D_Month,'Monthly metrics'!$C$8,D_DN,"Night") -> 75.2
H28: Extreme share | I28: ='Monthly metrics'!$J$8 -> 0.12269129 | J28: =MIN('Monthly metrics'!$J$8:$J$10) -> 0.12149201 | K28: =MAX('Monthly metrics'!$J$8:$J$10) -> 0.12941696 | L28: ='Monthly metrics'!$J$11 -> 0.12415239 | M28: =COUNTIFS(D_Month,'Monthly metrics'!$C$8,D_DN,"Day",D_Ext,TRUE())/COUNTIFS(D_Month,'Monthly metrics'!$C$8,D_DN,"Day") -> 0.15231788 | N28: =COUNTIFS(D_Month,'Monthly metrics'!$C$8,D_DN,"Night",D_Ext,TRUE())/COUNTIFS(D_Month,'Monthly metrics'!$C$8,D_DN,"Night") -> 0.098625224
H29: Upper extremes | I29: ='Monthly metrics'!$K$8 -> 137 | J29: =MIN('Monthly metrics'!$K$8:$K$10) -> 137 | K29: =MAX('Monthly metrics'!$K$8:$K$10) -> 171 | L29: ='Monthly metrics'!$K$11 -> 478 | M29: =COUNTIFS(D_Month,'Monthly metrics'!$C$8,D_DN,"Day",D_Dir,"upper") -> 94 | N29: =COUNTIFS(D_Month,'Monthly metrics'!$C$8,D_DN,"Night",D_Dir,"upper") -> 43
H30: Lower extremes | I30: ='Monthly metrics'!$L$8 -> 235 | J30: =MIN('Monthly metrics'!$L$8:$L$10) -> 123 | K30: =MAX('Monthly metrics'!$L$8:$L$10) -> 235 | L30: ='Monthly metrics'!$L$11 -> 529 | M30: =COUNTIFS(D_Month,'Monthly metrics'!$C$8,D_DN,"Day",D_Dir,"lower") -> 113 | N30: =COUNTIFS(D_Month,'Monthly metrics'!$C$8,D_DN,"Night",D_Dir,"lower") -> 122
H31: Sustained deviation (h) | I31: ='Monthly metrics'!$O$8 -> 235.78333 | J31: =MIN('Monthly metrics'!$O$8:$O$10) -> 235.78333 | K31: =MAX('Monthly metrics'!$O$8:$O$10) -> 251.335 | L31: ='Monthly metrics'!$O$11 -> 733.43667 | M31: =(COUNTIFS(D_Month,'Monthly metrics'!$C$8,D_DN,"Day",D_State,"Persistent")+COUNTIFS(D_Month,'Monthly metrics'!$C$8,D_DN,"Day",D_Conf,TRUE()))*'Monthly metrics'!$D$5/60 -> 88.293333 | N31: =(COUNTIFS(D_Month,'Monthly metrics'!$C$8,D_DN,"Night",D_State,"Persistent")+COUNTIFS(D_Month,'Monthly metrics'!$C$8,D_DN,"Night",D_Conf,TRUE()))*'Monthly metrics'!$D$5/60 -> 147.49
H32: Confirmed share | I32: ='Monthly metrics'!$P$8 -> 0.18799472 | J32: =MIN('Monthly metrics'!$P$8:$P$10) -> 0.18799472 | K32: =MAX('Monthly metrics'!$P$8:$P$10) -> 0.33392226 | L32: ='Monthly metrics'!$P$11 -> 0.24953766 | M32: =COUNTIFS(D_Month,'Monthly metrics'!$C$8,D_DN,"Day",D_Conf,TRUE())/COUNTIFS(D_Month,'Monthly metrics'!$C$8,D_DN,"Day") -> 0.13833701 | N32: =COUNTIFS(D_Month,'Monthly metrics'!$C$8,D_DN,"Night",D_Conf,TRUE())/COUNTIFS(D_Month,'Monthly metrics'!$C$8,D_DN,"Night") -> 0.22833234
H33: Material changes per day | I33: ='Monthly metrics'!$S$8 -> 4.2903226 | J33: =MIN('Monthly metrics'!$S$8:$S$10) -> 3.24 | K33: =MAX('Monthly metrics'!$S$8:$S$10) -> 4.2903226 | L33: ='Monthly metrics'!$S$11 -> 3.9186047 | M33: Not relevant | N33: Not relevant
H34: Mean materiality score | I34: ='Monthly metrics'!$T$8 -> 0.2142379 | J34: =MIN('Monthly metrics'!$T$8:$T$10) -> 0.2142379 | K34: =MAX('Monthly metrics'!$T$8:$T$10) -> 0.2695333 | L34: ='Monthly metrics'!$T$11 -> 0.23689843 | M34: =AVERAGEIFS(D_Score,D_Month,'Monthly metrics'!$C$8,D_DN,"Day") -> 0.19869249 | N34: =AVERAGEIFS(D_Score,D_Month,'Monthly metrics'!$C$8,D_DN,"Night") -> 0.22686563
H35: Max |Z| | I35: ='Monthly metrics'!$V$8 -> 4.2485292 | J35: =MIN('Monthly metrics'!$V$8:$V$10) -> 4.2485292 | K35: =MAX('Monthly metrics'!$V$8:$V$10) -> 4.2485292 | L35: ='Monthly metrics'!$V$11 -> 4.2485292 | M35: =_xlfn.MAXIFS(D_AbsZ,D_Month,'Monthly metrics'!$C$8,D_DN,"Day") -> 4.2485292 | N35: =_xlfn.MAXIFS(D_AbsZ,D_Month,'Monthly metrics'!$C$8,D_DN,"Night") -> 4.2485292
H36: Data gap hours | I36: ='Monthly metrics'!$X$8 -> 54.822778 | J36: =MIN('Monthly metrics'!$X$8:$X$10) -> 40.353889 | K36: =MAX('Monthly metrics'!$X$8:$X$10) -> 60.713889 | L36: ='Monthly metrics'!$X$11 -> 155.89056 | M36: Not relevant | N36: Not relevant
H38: * Best = lowest month, Worst = highest month for each measure (for Mean/Min/Max value: simply the lowest and highest month).
H39: * Max |Z| is capped at 4.25 with a 20-reading rolling window ((W−1)/√W), so it is the same in every month; use Extreme share and the events instead.
H40: * Settings: Rolling Mean/Std, Window 20, K_E 2.0, K_P 1.0, N_P 3, N_M 7, K_M 1.2, N_EXIT 1, ROC h 1, ROC window 20, ROC_K 2.0, frequency 10 / min 2.
B42: Readings against the normal range
B43: Grey band = normal range (moving average ± 2σ). Dots outside it are Extreme readings: orange = upper, blue = lower.
B68: Events in this month
B69: View all events
B70: * Sorted by materiality score (highest first). Action: Investigate = Confirmed shift, Review = Persistent, Monitor = shorter events. Click the Action to see the readings.
B72: Start | D72: End | F72: Duration (h) | H72: Highest state | I72: Direction | J72: Peak value | K72: Max |Z| | L72: Mean |Z| | M72: Max materiality | N72: Day/Night | O72: Action
B73: 45993.344 | D73: 45993.479 | F73: 3.4794444 | H73: Confirmed/Materialized Shift | I73: upper | J73: 74.9174 | K73: 3.7830251 | L73: 2.0473129 | M73: 0.7019 | N73: Day | O73: Investigate
B74: 46006.416 | D74: 46006.462 | F74: 1.3327778 | H74: Confirmed/Materialized Shift | I74: upper | J74: 74.0714 | K74: 3.7804442 | L74: 2.7600932 | M74: 0.7004 | N74: Day | O74: Investigate
...

Sheet Jan 2026
B2: We compared each reading with its own rolling baseline using the settings below | K2: ="Rank by mean materiality: "&'Monthly metrics'!$AB$9&" of 3 months (1 = most issues)" -> Rank by mean materiality: 2 of 3 months (1 = most issues)
B3: ="Sensor: Jensen Beach AHU 1 (°F), Period: January 2026, Value range: "&TEXT('Monthly metrics'!$G$9,"0.0")&" – "&TEXT('Monthly metrics'!$H$9,"0.0")&" °F" -> Sensor: Jensen Beach AHU 1 (°F), Period: January 2026, Value range: 66.2 – 75.5 °F | K3: Report generated: 10/08/2026 12:28
B5: < Back to summary worksheet
B6: Analysis funnel
B7: ="Readings in this month: "&TEXT('Monthly metrics'!$D$9,"#,##0") -> Readings in this month: 2,815 | F7: vs other months (3) | H7: Recommendations to improve | L7: Why have we recommended this?
D9: Extreme readings | I9: This month | J9: Best month | K9: Worst month
D10: Share of readings | F10: Rank vs other months | H10: ● Review what changed when the level shifted | I10: ='Monthly metrics'!$P$9 -> 0.24795737 | J10: =MIN('Monthly metrics'!$P$8:$P$10) -> 0.18799472 | K10: =MAX('Monthly metrics'!$P$8:$P$10) -> 0.33392226 | L10: ="Confirmed shift share: "&TEXT('Monthly metrics'!$P$9,"0%")&" of readings ("&TEXT('Monthly metrics'!$N$9*'Monthly metrics'!$D$5/60,"0")&" h). The value stayed away from its baseline for 7+ readings with mean |Z| ≥ 1.2 - check setpoint or schedule changes, sensor drift or an equipment fault." -> Confirmed shift share: 25% of readings (175 h). The value stayed away from its baseline for 7+ readings with mean |Z| ≥ 1.2 - check setpoint or schedule changes, sensor drift or an equipment fault.
D11: ='Monthly metrics'!$J$9 -> 0.12149201 | F11: ='Monthly metrics'!$Y$9 -> 3
D13: Sustained deviations | H13: ● Check the day/night pattern before acting on single extremes | I13: ='Monthly metrics'!$J$9 -> 0.12149201 | J13: =MIN('Monthly metrics'!$J$8:$J$10) -> 0.12149201 | K13: =MAX('Monthly metrics'!$J$8:$J$10) -> 0.12941696 | L13: ="Upper extremes happen mostly by day and lower extremes mostly at night ("&TEXT('Monthly metrics'!$K$9,"0")&" upper, "&TEXT('Monthly metrics'!$L$9,"0")&" lower). With a 20-reading (5 h) baseline, the normal daily swing itself is flagged. If the swing is intended (setback), consider Window = 96 (24 h)." -> Upper extremes happen mostly by day and lower extremes mostly at night (171 upper, 171 lower). With a 20-reading (5 h) baseline, the normal daily swing itself is flagged. If the swing is intended (setback), consider Window = 96 (24 h).
D14: Hours (Persistent + Confirmed) | F14: Rank vs other months
D15: ='Monthly metrics'!$O$9 -> 251.335 | F15: ='Monthly metrics'!$Z$9 -> 1
H16: ● Check for hunting or short-cycling | I16: ='Monthly metrics'!$S$9 -> 4.1 | J16: =MIN('Monthly metrics'!$S$8:$S$10) -> 3.24 | K16: =MAX('Monthly metrics'!$S$8:$S$10) -> 4.2903226 | L16: ="Material changes: "&TEXT('Monthly metrics'!$S$9,"0.0")&" per day - fast changes that repeat within 10 readings. Check valve/damper control loops and compressor or fan staging." -> Material changes: 4.1 per day - fast changes that repeat within 10 readings. Check valve/damper control loops and compressor or fan staging.
D17: Material changes
D18: Per day | F18: Rank vs other months
D19: ='Monthly metrics'!$S$9 -> 4.1 | F19: ='Monthly metrics'!$AA$9 -> 2 | H19: ● Fix the data gaps | I19: ='Monthly metrics'!$X$9 -> 60.713889 | J19: =MIN('Monthly metrics'!$X$8:$X$10) -> 40.353889 | K19: =MAX('Monthly metrics'!$X$8:$X$10) -> 60.713889 | L19: ="Missing data: "&TEXT('Monthly metrics'!$X$9,"0.0")&" h in gaps longer than three intervals. Events inside a gap cannot be detected." -> Missing data: 60.7 h in gaps longer than three intervals. Events inside a gap cannot be detected.
B23: More benchmarks
H24: Measure | I24: This month | J24: Best month | K24: Worst month | L24: Whole period | M24: This month – Day | N24: This month – Night
H25: Mean value | I25: ='Monthly metrics'!$F$9 -> 72.564037 | J25: =MIN('Monthly metrics'!$F$8:$F$10) -> 71.634218 | K25: =MAX('Monthly metrics'!$F$8:$F$10) -> 73.178845 | L25: ='Monthly metrics'!$F$11 -> 72.534323 | M25: =AVERAGEIFS(D_Value,D_Month,'Monthly metrics'!$C$9,D_DN,"Day") -> 72.616811 | N25: =AVERAGEIFS(D_Value,D_Month,'Monthly metrics'!$C$9,D_DN,"Night") -> 72.51914
H26: Min value | I26: ='Monthly metrics'!$G$9 -> 66.164 | J26: =MIN('Monthly metrics'!$G$8:$G$10) -> 65.0354 | K26: =MAX('Monthly metrics'!$G$8:$G$10) -> 67.8596 | L26: ='Monthly metrics'!$G$11 -> 65.0354 | M26: =_xlfn.MINIFS(D_Value,D_Month,'Monthly metrics'!$C$9,D_DN,"Day") -> 66.164 | N26: =_xlfn.MINIFS(D_Value,D_Month,'Monthly metrics'!$C$9,D_DN,"Night") -> 67.2944
H27: Max value | I27: ='Monthly metrics'!$H$9 -> 75.4826 | J27: =MIN('Monthly metrics'!$H$8:$H$10) -> 74.9174 | K27: =MAX('Monthly metrics'!$H$8:$H$10) -> 75.4826 | L27: ='Monthly metrics'!$H$11 -> 75.4826 | M27: =_xlfn.MAXIFS(D_Value,D_Month,'Monthly metrics'!$C$9,D_DN,"Day") -> 75.4826 | N27: =_xlfn.MAXIFS(D_Value,D_Month,'Monthly metrics'!$C$9,D_DN,"Night") -> 75.4826
H28: Extreme share | I28: ='Monthly metrics'!$J$9 -> 0.12149201 | J28: =MIN('Monthly metrics'!$J$8:$J$10) -> 0.12149201 | K28: =MAX('Monthly metrics'!$J$8:$J$10) -> 0.12941696 | L28: ='Monthly metrics'!$J$11 -> 0.12415239 | M28: =COUNTIFS(D_Month,'Monthly metrics'!$C$9,D_DN,"Day",D_Ext,TRUE())/COUNTIFS(D_Month,'Monthly metrics'!$C$9,D_DN,"Day") -> 0.1561051 | N28: =COUNTIFS(D_Month,'Monthly metrics'!$C$9,D_DN,"Night",D_Ext,TRUE())/COUNTIFS(D_Month,'Monthly metrics'!$C$9,D_DN,"Night") -> 0.092044707
H29: Upper extremes | I29: ='Monthly metrics'!$K$9 -> 171 | J29: =MIN('Monthly metrics'!$K$8:$K$10) -> 137 | K29: =MAX('Monthly metrics'!$K$8:$K$10) -> 171 | L29: ='Monthly metrics'!$K$11 -> 478 | M29: =COUNTIFS(D_Month,'Monthly metrics'!$C$9,D_DN,"Day",D_Dir,"upper") -> 141 | N29: =COUNTIFS(D_Month,'Monthly metrics'!$C$9,D_DN,"Night",D_Dir,"upper") -> 30
H30: Lower extremes | I30: ='Monthly metrics'!$L$9 -> 171 | J30: =MIN('Monthly metrics'!$L$8:$L$10) -> 123 | K30: =MAX('Monthly metrics'!$L$8:$L$10) -> 235 | L30: ='Monthly metrics'!$L$11 -> 529 | M30: =COUNTIFS(D_Month,'Monthly metrics'!$C$9,D_DN,"Day",D_Dir,"lower") -> 61 | N30: =COUNTIFS(D_Month,'Monthly metrics'!$C$9,D_DN,"Night",D_Dir,"lower") -> 110
H31: Sustained deviation (h) | I31: ='Monthly metrics'!$O$9 -> 251.335 | J31: =MIN('Monthly metrics'!$O$8:$O$10) -> 235.78333 | K31: =MAX('Monthly metrics'!$O$8:$O$10) -> 251.335 | L31: ='Monthly metrics'!$O$11 -> 733.43667 | M31: =(COUNTIFS(D_Month,'Monthly metrics'!$C$9,D_DN,"Day",D_State,"Persistent")+COUNTIFS(D_Month,'Monthly metrics'!$C$9,D_DN,"Day",D_Conf,TRUE()))*'Monthly metrics'!$D$5/60 -> 96.821667 | N31: =(COUNTIFS(D_Month,'Monthly metrics'!$C$9,D_DN,"Night",D_State,"Persistent")+COUNTIFS(D_Month,'Monthly metrics'!$C$9,D_DN,"Night",D_Conf,TRUE()))*'Monthly metrics'!$D$5/60 -> 154.51333
H32: Confirmed share | I32: ='Monthly metrics'!$P$9 -> 0.24795737 | J32: =MIN('Monthly metrics'!$P$8:$P$10) -> 0.18799472 | K32: =MAX('Monthly metrics'!$P$8:$P$10) -> 0.33392226 | L32: ='Monthly metrics'!$P$11 -> 0.24953766 | M32: =COUNTIFS(D_Month,'Monthly metrics'!$C$9,D_DN,"Day",D_Conf,TRUE())/COUNTIFS(D_Month,'Monthly metrics'!$C$9,D_DN,"Day") -> 0.19319938 | N32: =COUNTIFS(D_Month,'Monthly metrics'!$C$9,D_DN,"Night",D_Conf,TRUE())/COUNTIFS(D_Month,'Monthly metrics'!$C$9,D_DN,"Night") -> 0.29454306
H33: Material changes per day | I33: ='Monthly metrics'!$S$9 -> 4.1 | J33: =MIN('Monthly metrics'!$S$8:$S$10) -> 3.24 | K33: =MAX('Monthly metrics'!$S$8:$S$10) -> 4.2903226 | L33: ='Monthly metrics'!$S$11 -> 3.9186047 | M33: Not relevant | N33: Not relevant
H34: Mean materiality score | I34: ='Monthly metrics'!$T$9 -> 0.23505879 | J34: =MIN('Monthly metrics'!$T$8:$T$10) -> 0.2142379 | K34: =MAX('Monthly metrics'!$T$8:$T$10) -> 0.2695333 | L34: ='Monthly metrics'!$T$11 -> 0.23689843 | M34: =AVERAGEIFS(D_Score,D_Month,'Monthly metrics'!$C$9,D_DN,"Day") -> 0.21525054 | N34: =AVERAGEIFS(D_Score,D_Month,'Monthly metrics'!$C$9,D_DN,"Night") -> 0.25191078
H35: Max |Z| | I35: ='Monthly metrics'!$V$9 -> 4.2485292 | J35: =MIN('Monthly metrics'!$V$8:$V$10) -> 4.2485292 | K35: =MAX('Monthly metrics'!$V$8:$V$10) -> 4.2485292 | L35: ='Monthly metrics'!$V$11 -> 4.2485292 | M35: =_xlfn.MAXIFS(D_AbsZ,D_Month,'Monthly metrics'!$C$9,D_DN,"Day") -> 4.2485292 | N35: =_xlfn.MAXIFS(D_AbsZ,D_Month,'Monthly metrics'!$C$9,D_DN,"Night") -> 4.2485292
H36: Data gap hours | I36: ='Monthly metrics'!$X$9 -> 60.713889 | J36: =MIN('Monthly metrics'!$X$8:$X$10) -> 40.353889 | K36: =MAX('Monthly metrics'!$X$8:$X$10) -> 60.713889 | L36: ='Monthly metrics'!$X$11 -> 155.89056 | M36: Not relevant | N36: Not relevant
H38: * Best = lowest month, Worst = highest month for each measure (for Mean/Min/Max value: simply the lowest and highest month).
H39: * Max |Z| is capped at 4.25 with a 20-reading rolling window ((W−1)/√W), so it is the same in every month; use Extreme share and the events instead.
H40: * Settings: Rolling Mean/Std, Window 20, K_E 2.0, K_P 1.0, N_P 3, N_M 7, K_M 1.2, N_EXIT 1, ROC h 1, ROC window 20, ROC_K 2.0, frequency 10 / min 2.
B42: Readings against the normal range
B43: Grey band = normal range (moving average ± 2σ). Dots outside it are Extreme readings: orange = upper, blue = lower.
B68: Events in this month
B69: View all events
B70: * Sorted by materiality score (highest first). Action: Investigate = Confirmed shift, Review = Persistent, Monitor = shorter events. Click the Action to see the readings.
B72: Start | D72: End | F72: Duration (h) | H72: Highest state | I72: Direction | J72: Peak value | K72: Max |Z| | L72: Mean |Z| | M72: Max materiality | N72: Day/Night | O72: Action
B73: 46035.53 | D73: 46035.601 | F73: 1.95 | H73: Confirmed/Materialized Shift | I73: upper | J73: 74.0714 | K73: 3.4626496 | L73: 1.776158 | M73: 0.688 | N73: Day | O73: Investigate
B74: 46025.375 | D74: 46025.488 | F74: 2.9611111 | H74: Confirmed/Materialized Shift | I74: upper | J74: 72.941 | K74: 2.9016213 | L74: 2.1484206 | M74: 0.6791 | N74: Day | O74: Investigate
...

Sheet Feb 2026
B2: We compared each reading with its own rolling baseline using the settings below | K2: ="Rank by mean materiality: "&'Monthly metrics'!$AB$10&" of 3 months (1 = most issues)" -> Rank by mean materiality: 1 of 3 months (1 = most issues)
B3: ="Sensor: Jensen Beach AHU 1 (°F), Period: February 2026, Value range: "&TEXT('Monthly metrics'!$G$10,"0.0")&" – "&TEXT('Monthly metrics'!$H$10,"0.0")&" °F" -> Sensor: Jensen Beach AHU 1 (°F), Period: February 2026, Value range: 65.0 – 74.9 °F | K3: Report generated: 10/08/2026 12:28
B5: < Back to summary worksheet
B6: Analysis funnel
B7: ="Readings in this month: "&TEXT('Monthly metrics'!$D$10,"#,##0") -> Readings in this month: 2,264 | F7: vs other months (3) | H7: Recommendations to improve | L7: Why have we recommended this?
D9: Extreme readings | I9: This month | J9: Best month | K9: Worst month
D10: Share of readings | F10: Rank vs other months | H10: ● Review what changed when the level shifted | I10: ='Monthly metrics'!$P$10 -> 0.33392226 | J10: =MIN('Monthly metrics'!$P$8:$P$10) -> 0.18799472 | K10: =MAX('Monthly metrics'!$P$8:$P$10) -> 0.33392226 | L10: ="Confirmed shift share: "&TEXT('Monthly metrics'!$P$10,"0%")&" of readings ("&TEXT('Monthly metrics'!$N$10*'Monthly metrics'!$D$5/60,"0")&" h). The value stayed away from its baseline for 7+ readings with mean |Z| ≥ 1.2 - check setpoint or schedule changes, sensor drift or an equipment fault." -> Confirmed shift share: 33% of readings (190 h). The value stayed away from its baseline for 7+ readings with mean |Z| ≥ 1.2 - check setpoint or schedule changes, sensor drift or an equipment fault.
D11: ='Monthly metrics'!$J$10 -> 0.12941696 | F11: ='Monthly metrics'!$Y$10 -> 1
D13: Sustained deviations | H13: ● Check the day/night pattern before acting on single extremes | I13: ='Monthly metrics'!$J$10 -> 0.12941696 | J13: =MIN('Monthly metrics'!$J$8:$J$10) -> 0.12149201 | K13: =MAX('Monthly metrics'!$J$8:$J$10) -> 0.12941696 | L13: ="Upper extremes happen mostly by day and lower extremes mostly at night ("&TEXT('Monthly metrics'!$K$10,"0")&" upper, "&TEXT('Monthly metrics'!$L$10,"0")&" lower). With a 20-reading (5 h) baseline, the normal daily swing itself is flagged. If the swing is intended (setback), consider Window = 96 (24 h)." -> Upper extremes happen mostly by day and lower extremes mostly at night (170 upper, 123 lower). With a 20-reading (5 h) baseline, the normal daily swing itself is flagged. If the swing is intended (setback), consider Window = 96 (24 h).
D14: Hours (Persistent + Confirmed) | F14: Rank vs other months
D15: ='Monthly metrics'!$O$10 -> 246.31833 | F15: ='Monthly metrics'!$Z$10 -> 2
H16: ● Check for hunting or short-cycling | I16: ='Monthly metrics'!$S$10 -> 3.24 | J16: =MIN('Monthly metrics'!$S$8:$S$10) -> 3.24 | K16: =MAX('Monthly metrics'!$S$8:$S$10) -> 4.2903226 | L16: ="Material changes: "&TEXT('Monthly metrics'!$S$10,"0.0")&" per day - fast changes that repeat within 10 readings. Check valve/damper control loops and compressor or fan staging." -> Material changes: 3.2 per day - fast changes that repeat within 10 readings. Check valve/damper control loops and compressor or fan staging.
D17: Material changes
D18: Per day | F18: Rank vs other months
D19: ='Monthly metrics'!$S$10 -> 3.24 | F19: ='Monthly metrics'!$AA$10 -> 3 | H19: ● Fix the data gaps | I19: ='Monthly metrics'!$X$10 -> 40.353889 | J19: =MIN('Monthly metrics'!$X$8:$X$10) -> 40.353889 | K19: =MAX('Monthly metrics'!$X$8:$X$10) -> 60.713889 | L19: ="Missing data: "&TEXT('Monthly metrics'!$X$10,"0.0")&" h in gaps longer than three intervals. Events inside a gap cannot be detected." -> Missing data: 40.4 h in gaps longer than three intervals. Events inside a gap cannot be detected.
B23: More benchmarks
H24: Measure | I24: This month | J24: Best month | K24: Worst month | L24: Whole period | M24: This month – Day | N24: This month – Night
H25: Mean value | I25: ='Monthly metrics'!$F$10 -> 71.634218 | J25: =MIN('Monthly metrics'!$F$8:$F$10) -> 71.634218 | K25: =MAX('Monthly metrics'!$F$8:$F$10) -> 73.178845 | L25: ='Monthly metrics'!$F$11 -> 72.534323 | M25: =AVERAGEIFS(D_Value,D_Month,'Monthly metrics'!$C$10,D_DN,"Day") -> 71.747129 | N25: =AVERAGEIFS(D_Value,D_Month,'Monthly metrics'!$C$10,D_DN,"Night") -> 71.525035
H26: Min value | I26: ='Monthly metrics'!$G$10 -> 65.0354 | J26: =MIN('Monthly metrics'!$G$8:$G$10) -> 65.0354 | K26: =MAX('Monthly metrics'!$G$8:$G$10) -> 67.8596 | L26: ='Monthly metrics'!$G$11 -> 65.0354 | M26: =_xlfn.MINIFS(D_Value,D_Month,'Monthly metrics'!$C$10,D_DN,"Day") -> 65.0354 | N26: =_xlfn.MINIFS(D_Value,D_Month,'Monthly metrics'!$C$10,D_DN,"Night") -> 67.2944
H27: Max value | I27: ='Monthly metrics'!$H$10 -> 74.9174 | J27: =MIN('Monthly metrics'!$H$8:$H$10) -> 74.9174 | K27: =MAX('Monthly metrics'!$H$8:$H$10) -> 75.4826 | L27: ='Monthly metrics'!$H$11 -> 75.4826 | M27: =_xlfn.MAXIFS(D_Value,D_Month,'Monthly metrics'!$C$10,D_DN,"Day") -> 74.0714 | N27: =_xlfn.MAXIFS(D_Value,D_Month,'Monthly metrics'!$C$10,D_DN,"Night") -> 74.9174
H28: Extreme share | I28: ='Monthly metrics'!$J$10 -> 0.12941696 | J28: =MIN('Monthly metrics'!$J$8:$J$10) -> 0.12149201 | K28: =MAX('Monthly metrics'!$J$8:$J$10) -> 0.12941696 | L28: ='Monthly metrics'!$J$11 -> 0.12415239 | M28: =COUNTIFS(D_Month,'Monthly metrics'!$C$10,D_DN,"Day",D_Ext,TRUE())/COUNTIFS(D_Month,'Monthly metrics'!$C$10,D_DN,"Day") -> 0.17340521 | N28: =COUNTIFS(D_Month,'Monthly metrics'!$C$10,D_DN,"Night",D_Ext,TRUE())/COUNTIFS(D_Month,'Monthly metrics'!$C$10,D_DN,"Night") -> 0.086880973
H29: Upper extremes | I29: ='Monthly metrics'!$K$10 -> 170 | J29: =MIN('Monthly metrics'!$K$8:$K$10) -> 137 | K29: =MAX('Monthly metrics'!$K$8:$K$10) -> 171 | L29: ='Monthly metrics'!$K$11 -> 478 | M29: =COUNTIFS(D_Month,'Monthly metrics'!$C$10,D_DN,"Day",D_Dir,"upper") -> 164 | N29: =COUNTIFS(D_Month,'Monthly metrics'!$C$10,D_DN,"Night",D_Dir,"upper") -> 6
H30: Lower extremes | I30: ='Monthly metrics'!$L$10 -> 123 | J30: =MIN('Monthly metrics'!$L$8:$L$10) -> 123 | K30: =MAX('Monthly metrics'!$L$8:$L$10) -> 235 | L30: ='Monthly metrics'!$L$11 -> 529 | M30: =COUNTIFS(D_Month,'Monthly metrics'!$C$10,D_DN,"Day",D_Dir,"lower") -> 29 | N30: =COUNTIFS(D_Month,'Monthly metrics'!$C$10,D_DN,"Night",D_Dir,"lower") -> 94
H31: Sustained deviation (h) | I31: ='Monthly metrics'!$O$10 -> 246.31833 | J31: =MIN('Monthly metrics'!$O$8:$O$10) -> 235.78333 | K31: =MAX('Monthly metrics'!$O$8:$O$10) -> 251.335 | L31: ='Monthly metrics'!$O$11 -> 733.43667 | M31: =(COUNTIFS(D_Month,'Monthly metrics'!$C$10,D_DN,"Day",D_State,"Persistent")+COUNTIFS(D_Month,'Monthly metrics'!$C$10,D_DN,"Day",D_Conf,TRUE()))*'Monthly metrics'!$D$5/60 -> 106.35333 | N31: =(COUNTIFS(D_Month,'Monthly metrics'!$C$10,D_DN,"Night",D_State,"Persistent")+COUNTIFS(D_Month,'Monthly metrics'!$C$10,D_DN,"Night",D_Conf,TRUE()))*'Monthly metrics'!$D$5/60 -> 139.965
H32: Confirmed share | I32: ='Monthly metrics'!$P$10 -> 0.33392226 | J32: =MIN('Monthly metrics'!$P$8:$P$10) -> 0.18799472 | K32: =MAX('Monthly metrics'!$P$8:$P$10) -> 0.33392226 | L32: ='Monthly metrics'!$P$11 -> 0.24953766 | M32: =COUNTIFS(D_Month,'Monthly metrics'!$C$10,D_DN,"Day",D_Conf,TRUE())/COUNTIFS(D_Month,'Monthly metrics'!$C$10,D_DN,"Day") -> 0.27583109 | N32: =COUNTIFS(D_Month,'Monthly metrics'!$C$10,D_DN,"Night",D_Conf,TRUE())/COUNTIFS(D_Month,'Monthly metrics'!$C$10,D_DN,"Night") -> 0.39009557
H33: Material changes per day | I33: ='Monthly metrics'!$S$10 -> 3.24 | J33: =MIN('Monthly metrics'!$S$8:$S$10) -> 3.24 | K33: =MAX('Monthly metrics'!$S$8:$S$10) -> 4.2903226 | L33: ='Monthly metrics'!$S$11 -> 3.9186047 | M33: Not relevant | N33: Not relevant
H34: Mean materiality score | I34: ='Monthly metrics'!$T$10 -> 0.2695333 | J34: =MIN('Monthly metrics'!$T$8:$T$10) -> 0.2142379 | K34: =MAX('Monthly metrics'!$T$8:$T$10) -> 0.2695333 | L34: ='Monthly metrics'!$T$11 -> 0.23689843 | M34: =AVERAGEIFS(D_Score,D_Month,'Monthly metrics'!$C$10,D_DN,"Day") -> 0.25101698 | N34: =AVERAGEIFS(D_Score,D_Month,'Monthly metrics'!$C$10,D_DN,"Night") -> 0.28743831
H35: Max |Z| | I35: ='Monthly metrics'!$V$10 -> 4.2485292 | J35: =MIN('Monthly metrics'!$V$8:$V$10) -> 4.2485292 | K35: =MAX('Monthly metrics'!$V$8:$V$10) -> 4.2485292 | L35: ='Monthly metrics'!$V$11 -> 4.2485292 | M35: =_xlfn.MAXIFS(D_AbsZ,D_Month,'Monthly metrics'!$C$10,D_DN,"Day") -> 3.2557099 | N35: =_xlfn.MAXIFS(D_AbsZ,D_Month,'Monthly metrics'!$C$10,D_DN,"Night") -> 4.2485292
H36: Data gap hours | I36: ='Monthly metrics'!$X$10 -> 40.353889 | J36: =MIN('Monthly metrics'!$X$8:$X$10) -> 40.353889 | K36: =MAX('Monthly metrics'!$X$8:$X$10) -> 60.713889 | L36: ='Monthly metrics'!$X$11 -> 155.89056 | M36: Not relevant | N36: Not relevant
H38: * Best = lowest month, Worst = highest month for each measure (for Mean/Min/Max value: simply the lowest and highest month).
H39: * Max |Z| is capped at 4.25 with a 20-reading rolling window ((W−1)/√W), so it is the same in every month; use Extreme share and the events instead.
H40: * Settings: Rolling Mean/Std, Window 20, K_E 2.0, K_P 1.0, N_P 3, N_M 7, K_M 1.2, N_EXIT 1, ROC h 1, ROC window 20, ROC_K 2.0, frequency 10 / min 2.
B42: Readings against the normal range
B43: Grey band = normal range (moving average ± 2σ). Dots outside it are Extreme readings: orange = upper, blue = lower.
B68: Events in this month
B69: View all events
B70: * Sorted by materiality score (highest first). Action: Investigate = Confirmed shift, Review = Persistent, Monitor = shorter events. Click the Action to see the readings.
B72: Start | D72: End | F72: Duration (h) | H72: Highest state | I72: Direction | J72: Peak value | K72: Max |Z| | L72: Mean |Z| | M72: Max materiality | N72: Day/Night | O72: Action
B73: 46069.375 | D73: 46069.469 | F73: 2.5041667 | H73: Confirmed/Materialized Shift | I73: upper | J73: 74.0714 | K73: 2.9240383 | L73: 1.8502528 | M73: 0.6851 | N73: Day | O73: Investigate
B74: 46059.344 | D74: 46059.572 | F74: 5.7238889 | H74: Confirmed/Materialized Shift | I74: upper | J74: 72.6584 | K74: 2.9638579 | L74: 2.0693965 | M74: 0.6833 | N74: Day | O74: Investigate
...

Sheet Events
B2: All events
B3: One row per event (from Extreme triggered until Persistence ends), sorted by start time. Derived from the Data tab.
B5: Start | C5: End | D5: Duration (h) | E5: Direction | F5: Peak value | G5: Max |Z| | H5: Mean |Z| (event) | I5: Highest state | J5: Max materiality score | K5: Day/Night at start | L5: Month key | M5: Action | N5: Readings
B6: 45992.758 | C6: 45992.779 | D6: 0.75527778 | E6: lower | F6: 72.095 | G6: 2.5709806 | H6: 2.226829 | I6: Persistent | J6: 0.4351 | K6: Night | L6: 202512 | M6: Review | N6: View readings
B7: 45993.344 | C7: 45993.479 | D7: 3.4794444 | E7: upper | F7: 74.9174 | G7: 3.7830251 | H7: 2.0473129 | I7: Confirmed/Materialized Shift | J7: 0.7019 | K7: Day | L7: 202512 | M7: Investigate | N7: View readings
B8: 45993.79 | C8: 45993.945 | D8: 3.9688889 | E8: upper | F8: 74.0714 | G8: 2.687603 | H8: 1.7012734 | I8: Confirmed/Materialized Shift | J8: 0.5529 | K8: Night | L8: 202512 | M8: Investigate | N8: View readings
B9: 45994.09 | C9: 45994.09 | D9: 0.25083333 | E9: upper | F9: 74.3522 | G9: 3.0733303 | H9: 3.0733303 | I9: Extreme triggered | J9: 0.2906 | K9: Night | L9: 202512 | M9: Monitor | N9: View readings
B10: 45994.111 | C10: 45994.111 | D10: 0.25083333 | E10: upper | F10: 74.3522 | G10: 2.9240383 | H10: 2.9240383 | I10: Extreme triggered | J10: 0.3378 | K10: Night | L10: 202512 | M10: Monitor | N10: View readings
B11: 45994.162 | C11: 45994.173 | D11: 0.50166667 | E11: upper | F11: 74.3522 | G11: 2.3202011 | H11: 2.13478 | I11: Extreme/elevated | J11: 0.3585 | K11: Night | L11: 202512 | M11: Monitor | N11: View readings
B12: 45994.375 | C12: 45994.416 | D12: 1.2383333 | E12: lower | F12: 72.095 | G12: 4.1266192 | H12: 2.7441399 | I12: Persistent | J12: 0.4324 | K12: Day | L12: 202512 | M12: Review | N12: View readings
B13: 45994.79 | C13: 45994.883 | D13: 2.4808333 | E13: upper | F13: 73.7888 | G13: 2.2292129 | H13: 1.6161567 | I13: Confirmed/Materialized Shift | J13: 0.519 | K13: Night | L13: 202512 | M13: Investigate | N13: View readings
B14: 45994.997 | C14: 45995.204 | D14: 5.2247222 | E14: lower | F14: 72.6584 | G14: 2.4712634 | H14: 1.5675807 | I14: Confirmed/Materialized Shift | J14: 0.5389 | K14: Night | L14: 202512 | M14: Investigate | N14: View readings
B15: 45995.297 | C15: 45995.308 | D15: 0.50138889 | E15: lower | F15: 72.095 | G15: 2.1158376 | H15: 1.99461 | I15: Extreme/elevated | J15: 0.2963 | K15: Day | L15: 202512 | M15: Monitor | N15: View readings
B16: 45995.365 | C16: 45995.461 | D16: 2.5597222 | E16: upper | F16: 74.0714 | G16: 2.6216324 | H16: 1.7921224 | I16: Confirmed/Materialized Shift | J16: 0.5504 | K16: Day | L16: 202512 | M16: Investigate | N16: View readings
B17: 45995.676 | C17: 45995.759 | D17: 2.2408333 | E17: lower | F17: 72.095 | G17: 2.7404113 | H17: 2.219319 | I17: Confirmed/Materialized Shift | J17: 0.5588 | K17: Day | L17: 202512 | M17: Investigate | N17: View readings
... B294: 46078.334 | C294: 46078.468 | D294: 3.4794444 | E294: upper | F294: 72.3758 | G294: 2.5784944 | H294: 2.2424373 | I294: Confirmed/Materialized Shift | J294: 0.629 | K294: Day | L294: 202602 | M294: Investigate | N294: View readings

Sheet Daily overview
B2: Daily overview
B3: One row per day with data. All figures are formulas over the Data tab.
B5: Date | C5: Readings | D5: Mean value | E5: Min value | F5: Max value | G5: Extreme readings | H5: Extreme share | I5: Persistent periods | J5: Confirmed shift periods | K5: Abnormal changes | L5: Material changes | M5: Max materiality score
B6: 45992 | C6: =COUNTIF(D_Date,$B6) -> 51 | D6: =AVERAGEIF(D_Date,$B6,D_Value) -> 73.267788 | E6: =_xlfn.MINIFS(D_Value,D_Date,$B6) -> 72.095 | F6: =_xlfn.MAXIFS(D_Value,D_Date,$B6) -> 74.6348 | G6: =COUNTIFS(D_Date,$B6,D_Ext,TRUE()) -> 4 | H6: =G6/C6 -> 0.078431373 | I6: =COUNTIFS(D_Date,$B6,D_State,"Persistent") -> 3 | J6: =COUNTIFS(D_Date,$B6,D_Conf,TRUE()) -> 0 | K6: =COUNTIFS(D_Date,$B6,D_Abn,TRUE()) -> 2 | L6: =COUNTIFS(D_Date,$B6,D_MatChg,TRUE()) -> 1 | M6: =_xlfn.MAXIFS(D_Score,D_Date,$B6) -> 0.4351
B7: 45993 | C7: =COUNTIF(D_Date,$B7) -> 101 | D7: =AVERAGEIF(D_Date,$B7,D_Value) -> 73.480804 | E7: =_xlfn.MINIFS(D_Value,D_Date,$B7) -> 72.095 | F7: =_xlfn.MAXIFS(D_Value,D_Date,$B7) -> 74.9174 | G7: =COUNTIFS(D_Date,$B7,D_Ext,TRUE()) -> 11 | H7: =G7/C7 -> 0.10891089 | I7: =COUNTIFS(D_Date,$B7,D_State,"Persistent") -> 8 | J7: =COUNTIFS(D_Date,$B7,D_Conf,TRUE()) -> 20 | K7: =COUNTIFS(D_Date,$B7,D_Abn,TRUE()) -> 8 | L7: =COUNTIFS(D_Date,$B7,D_MatChg,TRUE()) -> 5 | M7: =_xlfn.MAXIFS(D_Score,D_Date,$B7) -> 0.7019
B8: 45994 | C8: =COUNTIF(D_Date,$B8) -> 101 | D8: =AVERAGEIF(D_Date,$B8,D_Value) -> 73.464194 | E8: =_xlfn.MINIFS(D_Value,D_Date,$B8) -> 72.095 | F8: =_xlfn.MAXIFS(D_Value,D_Date,$B8) -> 74.3522 | G8: =COUNTIFS(D_Date,$B8,D_Ext,TRUE()) -> 9 | H8: =G8/C8 -> 0.089108911 | I8: =COUNTIFS(D_Date,$B8,D_State,"Persistent") -> 7 | J8: =COUNTIFS(D_Date,$B8,D_Conf,TRUE()) -> 4 | K8: =COUNTIFS(D_Date,$B8,D_Abn,TRUE()) -> 8 | L8: =COUNTIFS(D_Date,$B8,D_MatChg,TRUE()) -> 5 | M8: =_xlfn.MAXIFS(D_Score,D_Date,$B8) -> 0.519
B9: 45995 | C9: =COUNTIF(D_Date,$B9) -> 103 | D9: =AVERAGEIF(D_Date,$B9,D_Value) -> 73.242893 | E9: =_xlfn.MINIFS(D_Value,D_Date,$B9) -> 72.095 | F9: =_xlfn.MAXIFS(D_Value,D_Date,$B9) -> 74.0714 | G9: =COUNTIFS(D_Date,$B9,D_Ext,TRUE()) -> 15 | H9: =G9/C9 -> 0.14563107 | I9: =COUNTIFS(D_Date,$B9,D_State,"Persistent") -> 12 | J9: =COUNTIFS(D_Date,$B9,D_Conf,TRUE()) -> 25 | K9: =COUNTIFS(D_Date,$B9,D_Abn,TRUE()) -> 6 | L9: =COUNTIFS(D_Date,$B9,D_MatChg,TRUE()) -> 4 | M9: =_xlfn.MAXIFS(D_Score,D_Date,$B9) -> 0.5588
B10: 45996 | C10: =COUNTIF(D_Date,$B10) -> 103 | D10: =AVERAGEIF(D_Date,$B10,D_Value) -> 73.338852 | E10: =_xlfn.MINIFS(D_Value,D_Date,$B10) -> 72.095 | F10: =_xlfn.MAXIFS(D_Value,D_Date,$B10) -> 74.3522 | G10: =COUNTIFS(D_Date,$B10,D_Ext,TRUE()) -> 15 | H10: =G10/C10 -> 0.14563107 | I10: =COUNTIFS(D_Date,$B10,D_State,"Persistent") -> 15 | J10: =COUNTIFS(D_Date,$B10,D_Conf,TRUE()) -> 18 | K10: =COUNTIFS(D_Date,$B10,D_Abn,TRUE()) -> 10 | L10: =COUNTIFS(D_Date,$B10,D_MatChg,TRUE()) -> 8 | M10: =_xlfn.MAXIFS(D_Score,D_Date,$B10) -> 0.6077
B11: 45997 | C11: =COUNTIF(D_Date,$B11) -> 102 | D11: =AVERAGEIF(D_Date,$B11,D_Value) -> 73.674906 | E11: =_xlfn.MINIFS(D_Value,D_Date,$B11) -> 71.8124 | F11: =_xlfn.MAXIFS(D_Value,D_Date,$B11) -> 75.2 | G11: =COUNTIFS(D_Date,$B11,D_Ext,TRUE()) -> 21 | H11: =G11/C11 -> 0.20588235 | I11: =COUNTIFS(D_Date,$B11,D_State,"Persistent") -> 20 | J11: =COUNTIFS(D_Date,$B11,D_Conf,TRUE()) -> 15 | K11: =COUNTIFS(D_Date,$B11,D_Abn,TRUE()) -> 10 | L11: =COUNTIFS(D_Date,$B11,D_MatChg,TRUE()) -> 7 | M11: =_xlfn.MAXIFS(D_Score,D_Date,$B11) -> 0.628
B12: 45998 | C12: =COUNTIF(D_Date,$B12) -> 100 | D12: =AVERAGEIF(D_Date,$B12,D_Value) -> 74.234318 | E12: =_xlfn.MINIFS(D_Value,D_Date,$B12) -> 71.8124 | F12: =_xlfn.MAXIFS(D_Value,D_Date,$B12) -> 75.4826 | G12: =COUNTIFS(D_Date,$B12,D_Ext,TRUE()) -> 15 | H12: =G12/C12 -> 0.15 | I12: =COUNTIFS(D_Date,$B12,D_State,"Persistent") -> 14 | J12: =COUNTIFS(D_Date,$B12,D_Conf,TRUE()) -> 13 | K12: =COUNTIFS(D_Date,$B12,D_Abn,TRUE()) -> 8 | L12: =COUNTIFS(D_Date,$B12,D_MatChg,TRUE()) -> 5 | M12: =_xlfn.MAXIFS(D_Score,D_Date,$B12) -> 0.6229
B13: 45999 | C13: =COUNTIF(D_Date,$B13) -> 106 | D13: =AVERAGEIF(D_Date,$B13,D_Value) -> 73.964164 | E13: =_xlfn.MINIFS(D_Value,D_Date,$B13) -> 71.8124 | F13: =_xlfn.MAXIFS(D_Value,D_Date,$B13) -> 75.2 | G13: =COUNTIFS(D_Date,$B13,D_Ext,TRUE()) -> 10 | H13: =G13/C13 -> 0.094339623 | I13: =COUNTIFS(D_Date,$B13,D_State,"Persistent") -> 10 | J13: =COUNTIFS(D_Date,$B13,D_Conf,TRUE()) -> 7 | K13: =COUNTIFS(D_Date,$B13,D_Abn,TRUE()) -> 8 | L13: =COUNTIFS(D_Date,$B13,D_MatChg,TRUE()) -> 6 | M13: =_xlfn.MAXIFS(D_Score,D_Date,$B13) -> 0.6195
B14: 46000 | C14: =COUNTIF(D_Date,$B14) -> 99 | D14: =AVERAGEIF(D_Date,$B14,D_Value) -> 73.628945 | E14: =_xlfn.MINIFS(D_Value,D_Date,$B14) -> 73.2236 | F14: =_xlfn.MAXIFS(D_Value,D_Date,$B14) -> 74.0714 | G14: =COUNTIFS(D_Date,$B14,D_Ext,TRUE()) -> 10 | H14: =G14/C14 -> 0.1010101 | I14: =COUNTIFS(D_Date,$B14,D_State,"Persistent") -> 12 | J14: =COUNTIFS(D_Date,$B14,D_Conf,TRUE()) -> 7 | K14: =COUNTIFS(D_Date,$B14,D_Abn,TRUE()) -> 9 | L14: =COUNTIFS(D_Date,$B14,D_MatChg,TRUE()) -> 5 | M14: =_xlfn.MAXIFS(D_Score,D_Date,$B14) -> 0.5526
B15: 46001 | C15: =COUNTIF(D_Date,$B15) -> 102 | D15: =AVERAGEIF(D_Date,$B15,D_Value) -> 73.334476 | E15: =_xlfn.MINIFS(D_Value,D_Date,$B15) -> 72.095 | F15: =_xlfn.MAXIFS(D_Value,D_Date,$B15) -> 74.0714 | G15: =COUNTIFS(D_Date,$B15,D_Ext,TRUE()) -> 16 | H15: =G15/C15 -> 0.15686275 | I15: =COUNTIFS(D_Date,$B15,D_State,"Persistent") -> 16 | J15: =COUNTIFS(D_Date,$B15,D_Conf,TRUE()) -> 17 | K15: =COUNTIFS(D_Date,$B15,D_Abn,TRUE()) -> 7 | L15: =COUNTIFS(D_Date,$B15,D_MatChg,TRUE()) -> 4 | M15: =_xlfn.MAXIFS(D_Score,D_Date,$B15) -> 0.6077
B16: 46002 | C16: =COUNTIF(D_Date,$B16) -> 102 | D16: =AVERAGEIF(D_Date,$B16,D_Value) -> 72.534288 | E16: =_xlfn.MINIFS(D_Value,D_Date,$B16) -> 70.9646 | F16: =_xlfn.MAXIFS(D_Value,D_Date,$B16) -> 74.0714 | G16: =COUNTIFS(D_Date,$B16,D_Ext,TRUE()) -> 15 | H16: =G16/C16 -> 0.14705882 | I16: =COUNTIFS(D_Date,$B16,D_State,"Persistent") -> 13 | J16: =COUNTIFS(D_Date,$B16,D_Conf,TRUE()) -> 32 | K16: =COUNTIFS(D_Date,$B16,D_Abn,TRUE()) -> 8 | L16: =COUNTIFS(D_Date,$B16,D_MatChg,TRUE()) -> 3 | M16: =_xlfn.MAXIFS(D_Score,D_Date,$B16) -> 0.6024
B17: 46003 | C17: =COUNTIF(D_Date,$B17) -> 103 | D17: =AVERAGEIF(D_Date,$B17,D_Value) -> 72.066584 | E17: =_xlfn.MINIFS(D_Value,D_Date,$B17) -> 69.836 | F17: =_xlfn.MAXIFS(D_Value,D_Date,$B17) -> 73.7888 | G17: =COUNTIFS(D_Date,$B17,D_Ext,TRUE()) -> 12 | H17: =G17/C17 -> 0.11650485 | I17: =COUNTIFS(D_Date,$B17,D_State,"Persistent") -> 9 | J17: =COUNTIFS(D_Date,$B17,D_Conf,TRUE()) -> 39 | K17: =COUNTIFS(D_Date,$B17,D_Abn,TRUE()) -> 4 | L17: =COUNTIFS(D_Date,$B17,D_MatChg,TRUE()) -> 2 | M17: =_xlfn.MAXIFS(D_Score,D_Date,$B17) -> 0.6048
... B91: 46078 | C91: =COUNTIF(D_Date,$B91) -> 47 | D91: =AVERAGEIF(D_Date,$B91,D_Value) -> 68.543791 | E91: =_xlfn.MINIFS(D_Value,D_Date,$B91) -> 67.2944 | F91: =_xlfn.MAXIFS(D_Value,D_Date,$B91) -> 72.3758 | G91: =COUNTIFS(D_Date,$B91,D_Ext,TRUE()) -> 13 | H91: =G91/C91 -> 0.27659574 | I91: =COUNTIFS(D_Date,$B91,D_State,"Persistent") -> 4 | J91: =COUNTIFS(D_Date,$B91,D_Conf,TRUE()) -> 31 | K91: =COUNTIFS(D_Date,$B91,D_Abn,TRUE()) -> 4 | L91: =COUNTIFS(D_Date,$B91,D_MatChg,TRUE()) -> 3 | M91: =_xlfn.MAXIFS(D_Score,D_Date,$B91) -> 0.629

Sheet Monthly metrics
B2: Monthly metrics
B3: All figures are formulas over the Data tab. The month tabs and the Summary read from this table.
B5: Reading interval (minutes) | D5: 15.05 | E5: Median spacing of the timestamps in the data (15.05 min). Used to turn readings into hours.
B7: Month | C7: Month key | D7: Readings | E7: Days with data | F7: Mean value | G7: Min value | H7: Max value | I7: Extreme readings | J7: Extreme share | K7: Upper extremes | L7: Lower extremes | M7: Persistent periods | N7: Confirmed shift periods | O7: Sustained deviation (h) | P7: Confirmed share | Q7: Abnormal changes | R7: Material changes | S7: Material changes per day | T7: Mean materiality score | U7: Max materiality score | V7: Max |Z| | W7: Events | X7: Data gap hours | Y7: Rank: extreme share | Z7: Rank: sustained (h) | AA7: Rank: material changes/day | AB7: Rank: mean materiality
B8: Dec 2025 | C8: 202512 | D8: =COUNTIF(D_Month,$C8) -> 3032 | E8: =COUNTIFS('Daily overview'!$B$6:$B$91,">="&DATE(INT($C8/100),MOD($C8,100),1),'Daily overview'!$B$6:$B$91,"<"&DATE(INT($C8/100),MOD($C8,100)+1,1)) -> 31 | F8: =AVERAGEIF(D_Month,$C8,D_Value) -> 73.178845 | G8: =_xlfn.MINIFS(D_Value,D_Month,$C8) -> 67.8596 | H8: =_xlfn.MAXIFS(D_Value,D_Month,$C8) -> 75.4826 | I8: =COUNTIFS(D_Month,$C8,D_Ext,TRUE()) -> 372 | J8: =I8/D8 -> 0.12269129 | K8: =COUNTIFS(D_Month,$C8,D_Dir,"upper") -> 137 | L8: =COUNTIFS(D_Month,$C8,D_Dir,"lower") -> 235 | M8: =COUNTIFS(D_Month,$C8,D_State,"Persistent") -> 370 | N8: =COUNTIFS(D_Month,$C8,D_Conf,TRUE()) -> 570 | O8: =(M8+N8)*$D$5/60 -> 235.78333 | P8: =N8/D8 -> 0.18799472 | Q8: =COUNTIFS(D_Month,$C8,D_Abn,TRUE()) -> 226 | R8: =COUNTIFS(D_Month,$C8,D_MatChg,TRUE()) -> 133 | S8: =R8/E8 -> 4.2903226 | T8: =AVERAGEIF(D_Month,$C8,D_Score) -> 0.2142379 | U8: =_xlfn.MAXIFS(D_Score,D_Month,$C8) -> 0.7019 | V8: =_xlfn.MAXIFS(D_AbsZ,D_Month,$C8) -> 4.2485292 | W8: =COUNTIF(Events!$L:$L,$C8) -> 122 | X8: =SUMIF('Data gaps'!$I:$I,$C8,'Data gaps'!$D:$D) -> 54.822778 | Y8: =RANK(J8,$J$8:$J$10,0) -> 2 | Z8: =RANK(O8,$O$8:$O$10,0) -> 3 | AA8: =RANK(S8,$S$8:$S$10,0) -> 1 | AB8: =RANK(T8,$T$8:$T$10,0) -> 3
